Workbook

Sheet Offset by year
A1: Daniel Sewell, PhD
A2: Offset Summary
A3: July 2020 - present
O4: Projected
A5: SEWELL, DAN | F5: 2024-2025 | K5: 45474 | M5: 45505 | O5: 45536 | Q5: 45566 | S5: 45597 | U5: 45627 | W5: 45658 | Y5: 45689 | AA5: 45717 | AC5: 45748 | AE5: 45778 | AG5: 45809 | AI5: YTD SALARY SPLIT | AJ5: YTD OFFSET | AK5: YTD % Offset
A6: FUND | B6: ORG | C6: DEPT | D6: SDEPT | E6: GR-PR | F6: IACT | G6: OACT | H6: DACT | I6: FN | J6: ACCOUNT DESCRIPTION | K6: SALARY | L6: PERCENT | M6: SALARY | N6: PERCENT | O6: SALARY | P6: PERCENT | Q6: SALARY | R6: PERCENT | S6: SALARY | T6: PERCENT | U6: SALARY | V6: PERCENT | W6: SALARY | X6: PERCENT | Y6: SALARY | Z6: PERCENT | AA6: SALARY | AB6: PERCENT | AC6: SALARY | AD6: PERCENT | AE6: SALARY | AF6: PERCENT | AG6: SALARY | AH6: PERCENT
A7: 050 | B7: 20 | C7: 5220 | D7: 00000 | E7: 00000000 | F7: 5002 | G7: 000 | H7: 00000 | I7: 10 | J7: BIOSTAT GENERAL ACCT | K7: 1133.41 | L7: 0.09 | M7: 3339.97 | N7: 0.27 | O7: 4710.19 | P7: 0.38 | Q7: 4710.19 | R7: 0.38 | S7: 4710.19 | T7: 0.38 | U7: 1475.69 | V7: 0.15 | W7: 1475.69 | X7: 0.15 | Y7: 1475.69 | Z7: 0.15 | AA7: 1475.69 | AB7: 0.15 | AC7: 1475.69 | AD7: 0.15 | AE7: 1475.69 | AF7: 0.15 | AG7: 1475.69 | AH7: 0.15 | AI7: =SUM(K7,M7,O7,Q7,S7,U7,W7, Y7,AA7,AC7,AE7,AG7) -> 28933.78
A8: 510 | B8: 20 | C8: 5225 | D8: 00000 | E8: 11298401 | F8: 5002 | G8: 000 | H8: 00000 | I8: 20 | J8: PRC project | K8: 1200.03 | L8: 0.1 | M8: 1200.03 | N8: 0.1 | O8: 1200.03 | P8: 0.1 | Q8: 1200.03 | R8: 0.1 | S8: 1200.03 | T8: 0.1 | U8: 1200.03 | V8: 0.1 | W8: 1200.03 | X8: 0.1 | Y8: 1200.03 | Z8: 0.1 | AA8: 1200.03 | AB8: 0.1 | AC8: 1200.03 | AD8: 0.1 | AE8: 1200.03 | AF8: 0.1 | AG8: 1200.03 | AH8: 0.1 | AI8: =SUM(K8,M8,O8,Q8,S8,U8,W8, Y8,AA8,AC8,AE8,AG8) -> 14400.36
A9: 510 | B9: 11 | C9: 1110 | D9: 04000 | E9: 11317900 | F9: 5002 | G9: 000 | H9: 00000 | I9: 20 | J9: Segre: CDC MInD2 | K9: 1859.75 | L9: 0.15 | M9: 1859.75 | N9: 0.15 | O9: 1859.75 | P9: 0.15 | Q9: 1859.75 | R9: 0.15 | S9: 1859.75 | T9: 0.15 | U9: 1859.75 | V9: 0.15 | W9: 1859.75 | X9: 0.15 | Y9: 1859.75 | Z9: 0.15 | AA9: 1859.75 | AB9: 0.15 | AC9: 1859.75 | AD9: 0.15 | AE9: 1859.75 | AF9: 0.15 | AG9: 1859.75 | AH9: 0.15 | AI9: =SUM(K9,M9,O9,Q9,S9,U9,W9, Y9,AA9,AC9,AE9,AG9) -> 22317
A10: 510 | B10: 19 | C10: 4105 | D10: 00000 | E10: 11310300 | F10: 5002 | G10: 000 | H10: 00000 | I10: 20 | J10: L Polgreen: Pharm Hypertension | K10: 1094.99 | L10: 0.09 | M10: 1094.99 | N10: 0.09 | O10: 1094.99 | P10: 0.09 | Q10: 1094.99 | R10: 0.09 | S10: 1094.99 | T10: 0.09 | U10: 1094.99 | V10: 0.09 | W10: 1094.99 | X10: 0.09 | Y10: 1094.99 | Z10: 0.09 | AA10: 1094.99 | AB10: 0.09 | AC10: 1094.99 | AD10: 0.09 | AE10: 1094.99 | AF10: 0.09 | AG10: 1094.99 | AH10: 0.09 | AI10: =SUM(K10,M10,O10,Q10,S10,U10,W10, Y10,AA10,AC10,AE10,AG10) -> 13139.88
A11: 510 | B11: 20 | C11: 5220 | D11: 00000 | E11: 11328900 | F11: 5002 | G11: 000 | H11: 00000 | I11: 20 | J11: Zamba: ISIB | K11: 391.67 | L11: 0.03 | M11: 391.67 | N11: 0.03 | O11: 391.67 | P11: 0.03 | Q11: 391.67 | R11: 0.03 | S11: 391.67 | T11: 0.03 | U11: 391.67 | V11: 0.03 | W11: 391.67 | X11: 0.03 | Y11: 391.67 | Z11: 0.03 | AA11: 391.67 | AB11: 0.03 | AC11: 391.67 | AD11: 0.03 | AE11: 391.67 | AF11: 0.03 | AG11: 391.67 | AH11: 0.03 | AI11: =SUM(K11,M11,O11,Q11,S11,U11,W11, Y11,AA11,AC11,AE11,AG11) -> 4700.04
A12: 510 | B12: 20 | C12: 5220 | D12: 00000 | E12: 11320500 | F12: 5002 | G12: 000 | H12: 00000 | I12: 20 | J12: Sewell/Baker: PATHOME Main | K12: 3110 | L12: 0.25 | M12: 3110 | N12: 0.2515 | O12: 3110 | P12: 0.25 | Q12: 3110 | R12: 0.25 | S12: 3110 | T12: 0.25 | U12: 3110 | V12: 0.25 | W12: 3110 | X12: 0.25 | Y12: 3110 | Z12: 0.25 | AA12: 3110 | AB12: 0.25 | AC12: 3110 | AD12: 0.25 | AE12: 3110 | AF12: 0.25 | AG12: 3110 | AH12: 0.25 | AI12: =SUM(K12,M12,O12,Q12,S12,U12,W12, Y12,AA12,AC12,AE12,AG12) -> 37320
A13: 510 | B13: 20 | C13: 5220 | D13: 00000 | E13: 12404400 | F13: 5002 | G13: 000 | H13: 00000 | I13: 20 | J13: Sewell: UC Davis | K13: 3576.78 | L13: 0.29 | M13: 1370.22 | N13: 0.11 | P13: 0 | R13: 0 | T13: 0 | U13: 3234.5 | V13: 0.23 | W13: 3234.5 | X13: 0.23 | Y13: 3234.5 | Z13: 0.23 | AA13: 3234.5 | AB13: 0.23 | AC13: 3234.5 | AD13: 0.23 | AE13: 3234.5 | AF13: 0.23 | AG13: 3234.5 | AH13: 0.23 | AI13: =SUM(K13,M13,O13,Q13,S13,U13,W13, Y13,AA13,AC13,AE13,AG13) -> 27588.5
K14: =SUM(K7:K13) -> 12366.63 | L14: =SUM(L7:L13) -> 1 | M14: =SUM(M7:M13) -> 12366.63 | N14: =SUM(N7:N13) -> 1.0015 | O14: =SUM(O7:O13) -> 12366.63 | P14: =SUM(P7:P13) -> 1 | Q14: =SUM(Q7:Q13) -> 12366.63 | R14: =SUM(R7:R13) -> 1 | ... AI14: =SUM(AI7:AI13) -> 148399.56 | AJ14: =SUM(AI8:AI13) -> 119465.78 | AK14: =(AJ14/AI14) -> 0.80502786
A16: SEWELL, DAN | F16: 2023-2024 | K16: 45108 | M16: 45139 | O16: 45170 | Q16: 45200 | S16: 45231 | U16: 45261 | W16: 45292 | Y16: 45323 | AA16: 45352 | AC16: 45383 | AE16: 45413 | AG16: 45444 | AI16: YTD SALARY SPLIT | AJ16: YTD OFFSET | AK16: YTD % Offset
A17: FUND | B17: ORG | C17: DEPT | D17: SDEPT | E17: GR-PR | F17: IACT | G17: OACT | H17: DACT | I17: FN | J17: ACCOUNT DESCRIPTION | K17: SALARY | L17: PERCENT | M17: SALARY | N17: PERCENT | O17: SALARY | P17: PERCENT | Q17: SALARY | R17: PERCENT | S17: SALARY | T17: PERCENT | U17: SALARY | V17: PERCENT | W17: SALARY | X17: PERCENT | Y17: SALARY | Z17: PERCENT | AA17: SALARY | AB17: PERCENT | AC17: SALARY | AD17: PERCENT | AE17: SALARY | AF17: PERCENT | AG17: SALARY | AH17: PERCENT
A18: 050 | B18: 20 | C18: 5220 | D18: 00000 | E18: 00000000 | F18: 5002 | G18: 000 | H18: 00000 | I18: 10 | J18: BIOSTAT GENERAL ACCT | K18: 2455.27 | L18: 0.204 | M18: 3670.77 | N18: 0.31 | O18: 3670.77 | P18: 0.31 | Q18: 3670.77 | R18: 0.31 | S18: 3670.77 | T18: 0.31 | U18: 3670.77 | V18: 0.31 | W18: 3670.77 | X18: 0.31 | Y18: 3670.77 | Z18: 0.31 | AA18: 3670.77 | AB18: 0.31 | AC18: 3670.77 | AD18: 0.31 | AE18: 3670.77 | AF18: 0.31 | AG18: 3670.77 | AH18: 0.31 | AI18: =SUM(K18,M18,O18,Q18,S18,U18,W18, Y18,AA18,AC18,AE18,AG18) -> 42833.74
A19: 510 | B19: 20 | C19: 5225 | D19: 00000 | E19: 11298401 | F19: 5002 | G19: 000 | H19: 00000 | I19: 20 | J19: PRC project | K19: 1200.03 | L19: 0.1 | M19: 1200.03 | N19: 0.1 | O19: 1200.03 | P19: 0.1 | Q19: 1200.03 | R19: 0.1 | S19: 1200.03 | T19: 0.1 | U19: 1200.03 | V19: 0.1 | W19: 1200.03 | X19: 0.1 | Y19: 1200.03 | Z19: 0.1 | AA19: 1200.03 | AB19: 0.1 | AC19: 1200.03 | AD19: 0.1 | AE19: 1200.03 | AF19: 0.1 | AG19: 1200.03 | AH19: 0.1 | AI19: =SUM(K19,M19,O19,Q19,S19,U19,W19, Y19,AA19,AC19,AE19,AG19) -> 14400.36
A20: 510 | B20: 11 | C20: 1110 | D20: 04000 | E20: 11317900 | F20: 5002 | G20: 000 | H20: 00000 | I20: 20 | J20: Segre: CDC MInD2 | K20: 1859.75 | L20: 0.155 | M20: 1859.75 | N20: 0.155 | O20: 1859.75 | P20: 0.155 | Q20: 1859.75 | R20: 0.155 | S20: 1859.75 | T20: 0.155 | U20: 1859.75 | V20: 0.155 | W20: 1859.75 | X20: 0.155 | Y20: 1859.75 | Z20: 0.155 | AA20: 1859.75 | AB20: 0.155 | AC20: 1859.75 | AD20: 0.155 | AE20: 1859.75 | AF20: 0.155 | AG20: 1859.75 | AH20: 0.155 | AI20: =SUM(K20,M20,O20,Q20,S20,U20,W20, Y20,AA20,AC20,AE20,AG20) -> 22317
A21: 510 | B21: 19 | C21: 4105 | D21: 00000 | E21: 11310300 | F21: 5002 | G21: 000 | H21: 00000 | I21: 20 | J21: L Polgreen: Pharm Hypertension | K21: 1094.99 | L21: 0.09 | M21: 1094.99 | N21: 0.09 | O21: 1094.99 | P21: 0.09 | Q21: 1094.99 | R21: 0.09 | S21: 1094.99 | T21: 0.09 | U21: 1094.99 | V21: 0.09 | W21: 1094.99 | X21: 0.09 | Y21: 1094.99 | Z21: 0.09 | AA21: 1094.99 | AB21: 0.09 | AC21: 1094.99 | AD21: 0.09 | AE21: 1094.99 | AF21: 0.09 | AG21: 1094.99 | AH21: 0.09 | AI21: =SUM(K21,M21,O21,Q21,S21,U21,W21, Y21,AA21,AC21,AE21,AG21) -> 13139.88
A22: 510 | B22: 20 | C22: 5220 | D22: 00000 | E22: 11328900 | F22: 5002 | G22: 000 | H22: 00000 | I22: 20 | J22: Zamba: ISIB | K22: 391.67 | L22: 0.03 | M22: 391.67 | N22: 0.03 | O22: 391.67 | P22: 0.03 | Q22: 391.67 | R22: 0.03 | S22: 391.67 | T22: 0.03 | U22: 391.67 | V22: 0.03 | W22: 391.67 | X22: 0.03 | Y22: 391.67 | Z22: 0.03 | AA22: 391.67 | AB22: 0.03 | AC22: 391.67 | AD22: 0.03 | AE22: 391.67 | AF22: 0.03 | AG22: 391.67 | AH22: 0.03 | AI22: =SUM(K22,M22,O22,Q22,S22,U22,W22, Y22,AA22,AC22,AE22,AG22) -> 4700.04
A23: 510 | B23: 20 | C23: 5220 | D23: 00000 | E23: 11320500 | F23: 5002 | G23: 000 | H23: 00000 | I23: 20 | J23: Sewell/Baker: PATHOME Main | K23: 1903.8 | L23: 0.16 | M23: 1903.8 | N23: 0.16 | O23: 1903.8 | P23: 0.16 | Q23: 1903.8 | R23: 0.16 | S23: 1903.8 | T23: 0.16 | U23: 1903.8 | V23: 0.16 | W23: 1903.8 | X23: 0.16 | Y23: 1903.8 | Z23: 0.16 | AA23: 1903.8 | AB23: 0.16 | AC23: 1903.8 | AD23: 0.16 | AE23: 1903.8 | AF23: 0.16 | AG23: 1903.8 | AH23: 0.16 | AI23: =SUM(K23,M23,O23,Q23,S23,U23,W23, Y23,AA23,AC23,AE23,AG23) -> 22845.6
A24: 510 | B24: 20 | C24: 5240 | D24: 00000 | E24: 11320502 | F24: 5002 | G24: 000 | H24: 00000 | I24: 20 | J24: Baker/Sewell: PATHOME Supp | K24: 1215.5 | L24: 0.1 | AI24: =SUM(K24,M24,O24,Q24,S24,U24,W24, Y24,AA24,AC24,AE24,AG24) -> 1215.5
A25: 510 | B25: 20 | C25: 5220 | D25: 00000 | E25: 12404400 | F25: 5002 | G25: 000 | H25: 00000 | I25: 20 | J25: Sewell: UC Davis Enhancing EHR | K25: 1879.67 | L25: 0.156 | M25: 1879.67 | N25: 0.156 | O25: 1879.67 | P25: 0.156 | Q25: 1879.67 | R25: 0.156 | S25: 1879.67 | T25: 0.156 | U25: 1879.67 | V25: 0.156 | W25: 1879.67 | X25: 0.156 | Y25: 1879.67 | Z25: 0.156 | AA25: 1879.67 | AB25: 0.156 | AC25: 1879.67 | AD25: 0.156 | AE25: 1879.67 | AF25: 0.156 | AG25: 1879.67 | AH25: 0.156 | AI25: =SUM(K25,M25,O25,Q25,S25,U25,W25, Y25,AA25,AC25,AE25,AG25) -> 22556.04
K26: =SUM(K18:K25) -> 12000.68 | L26: =SUM(L18:L25) -> 0.995 | M26: =SUM(M18:M25) -> 12000.68 | N26: =SUM(N18:N25) -> 1.001 | O26: =SUM(O18:O25) -> 12000.68 | P26: =SUM(P18:P25) -> 1.001 | Q26: =SUM(Q18:Q25) -> 12000.68 | R26: =SUM(R18:R25) -> 1.001 | ... AI26: =SUM(AI18:AI25) -> 144008.16 | AJ26: =SUM(AI19:AI25) -> 101174.42 | AK26: =(AJ26/AI26) -> 0.70256033
A28: SEWELL, DAN | F28: 2022-2023 | K28: 44743 | M28: 44774 | O28: 44805 | Q28: 44835 | S28: 44866 | U28: 44896 | W28: 44927 | Y28: 44958 | AA28: 44986 | AC28: 45017 | AE28: 45047 | AG28: 45078 | AI28: YTD SALARY SPLIT | AJ28: YTD OFFSET | AK28: YTD % Offset
A29: FUND | B29: ORG | C29: DEPT | D29: SDEPT | E29: GR-PR | F29: IACT | G29: OACT | H29: DACT | I29: FN | J29: ACCOUNT DESCRIPTION | K29: SALARY | L29: PERCENT | M29: SALARY | N29: PERCENT | O29: SALARY | P29: PERCENT | Q29: SALARY | R29: PERCENT | S29: SALARY | T29: PERCENT | U29: SALARY | V29: PERCENT | W29: SALARY | X29: PERCENT | Y29: SALARY | Z29: PERCENT | AA29: SALARY | AB29: PERCENT | AC29: SALARY | AD29: PERCENT | AE29: SALARY | AF29: PERCENT | AG29: SALARY | AH29: PERCENT
A30: 050 | B30: 20 | C30: 5220 | D30: 00000 | E30: 00000000 | F30: 5002 | G30: 000 | H30: 00000 | I30: 10 | J30: BIOSTAT GENERAL ACCT | K30: 4763.39 | L30: 0.43 | M30: 4627.8 | N30: 0.42 | O30: 4627.8 | P30: 0.42 | Q30: 4627.8 | R30: 0.42 | S30: 3412.3 | T30: 0.31 | U30: 3412.3 | V30: 0.31 | W30: 3412.3 | X30: 0.31 | Y30: 3412.3 | Z30: 0.31 | AA30: 3412.3 | AB30: 0.31 | AC30: 3412.3 | AD30: 0.31 | AE30: 3412.3 | AF30: 0.31 | AG30: 3412.3 | AH30: 0.31 | AI30: =SUM(K30,M30,O30,Q30,S30,U30,W30, Y30,AA30,AC30,AE30,AG30) -> 45945.19
A31: 510 | B31: 20 | C31: 5225 | D31: 00000 | E31: 11298401 | F31: 5002 | G31: 000 | H31: 00000 | I31: 20 | J31: PRC project | K31: 1105 | L31: 0.1 | M31: 1105 | N31: 0.1 | O31: 1105 | P31: 0.1 | Q31: 1105 | R31: 0.1 | S31: 1105 | T31: 0.1 | U31: 1105 | V31: 0.1 | W31: 1105 | X31: 0.1 | Y31: 1105 | Z31: 0.1 | AA31: 1105 | AB31: 0.1 | AC31: 1105 | AD31: 0.1 | AE31: 1105 | AF31: 0.1 | AG31: 1105 | AH31: 0.1 | AI31: =SUM(K31,M31,O31,Q31,S31,U31,W31, Y31,AA31,AC31,AE31,AG31) -> 13260
A32: 510 | B32: 11 | C32: 1110 | D32: 04000 | E32: 11317903 | F32: 5002 | G32: 000 | H32: 00000 | I32: 20 | J32: Segre: CDC MInD2 | K32: 1673.83 | L32: 0.15 | M32: 1859.75 | N32: 0.17 | O32: 1859.75 | P32: 0.17 | Q32: 1859.75 | R32: 0.17 | S32: 1859.75 | T32: 0.17 | U32: 1859.75 | V32: 0.17 | W32: 1859.75 | X32: 0.17 | Y32: 1859.75 | Z32: 0.17 | AA32: 1859.75 | AB32: 0.17 | AC32: 1859.75 | AD32: 0.17 | AE32: 1859.75 | AF32: 0.17 | AG32: 1859.75 | AH32: 0.17 | AI32: =SUM(K32,M32,O32,Q32,S32,U32,W32, Y32,AA32,AC32,AE32,AG32) -> 22131.08
A33: 510 | B33: 19 | C33: 4105 | D33: 00000 | E33: 11310300 | F33: 5002 | G33: 000 | H33: 00000 | I33: 20 | J33: L Polgreen: Pharm Hypertension | K33: 1008.28 | L33: 0.09 | M33: 1008.28 | N33: 0.09 | O33: 1008.28 | P33: 0.09 | Q33: 1008.28 | R33: 0.09 | S33: 1008.28 | T33: 0.09 | U33: 1008.28 | V33: 0.09 | W33: 1008.28 | X33: 0.09 | Y33: 1008.28 | Z33: 0.09 | AA33: 1008.28 | AB33: 0.09 | AC33: 1008.28 | AD33: 0.09 | AE33: 1008.28 | AF33: 0.09 | AG33: 1008.28 | AH33: 0.09 | AI33: =SUM(K33,M33,O33,Q33,S33,U33,W33, Y33,AA33,AC33,AE33,AG33) -> 12099.36
A34: 510 | B34: 20 | C34: 5220 | D34: 00000 | E34: 11328900 | F34: 5002 | G34: 000 | H34: 00000 | I34: 20 | J34: Zamba: ISIB | K34: 442 | L34: 0.04 | M34: 391.67 | N34: 0.04 | O34: 391.67 | P34: 0.04 | Q34: 391.67 | R34: 0.04 | S34: 391.67 | T34: 0.04 | U34: 391.67 | V34: 0.04 | W34: 391.67 | X34: 0.04 | Y34: 391.67 | Z34: 0.04 | AA34: 391.67 | AB34: 0.04 | AC34: 391.67 | AD34: 0.04 | AE34: 391.67 | AF34: 0.04 | AG34: 391.67 | AH34: 0.04 | AI34: =SUM(K34,M34,O34,Q34,S34,U34,W34, Y34,AA34,AC34,AE34,AG34) -> 4750.37
A35: 510 | B35: 20 | C35: 5220 | D35: 00000 | E35: 11320500 | F35: 5002 | G35: 000 | H35: 00000 | I35: 20 | J35: Baker/Sewell: PATHOME Main | K35: 919.33 | L35: 0.083 | M35: 919.33 | N35: 0.083 | O35: 919.33 | P35: 0.083 | Q35: 919.33 | R35: 0.083 | S35: 919.33 | T35: 0.083 | U35: 919.33 | V35: 0.083 | W35: 919.33 | X35: 0.083 | Y35: 919.33 | Z35: 0.083 | AA35: 919.33 | AB35: 0.083 | AC35: 919.33 | AD35: 0.083 | AE35: 919.33 | AF35: 0.083 | AG35: 919.33 | AH35: 0.083 | AI35: =SUM(K35,M35,O35,Q35,S35,U35,W35, Y35,AA35,AC35,AE35,AG35) -> 11031.96
A36: 510 | B36: 20 | C36: 5240 | D36: 00000 | E36: 11320502 | F36: 5002 | G36: 000 | H36: 00000 | I36: 20 | J36: Baker/Sewell: PATHOME Supp | S36: 1215.5 | T36: 0.11 | U36: 1215.5 | V36: 0.11 | W36: 1215.5 | X36: 0.11 | Y36: 1215.5 | Z36: 0.11 | AA36: 1215.5 | AB36: 0.11 | AC36: 1215.5 | AD36: 0.11 | AE36: 1215.5 | AF36: 0.11 | AG36: 1215.5 | AH36: 0.11 | AI36: =SUM(K36,M36,O36,Q36,S36,U36,W36, Y36,AA36,AC36,AE36,AG36) -> 9724
A37: 510 | B37: 20 | C37: 5220 | D37: 00000 | E37: 12404400 | F37: 5002 | G37: 000 | H37: 00000 | I37: 20 | J37: Sewell: UC Davis Enhancing EHR | K37: 1138.17 | L37: 0.103 | M37: 1138.17 | N37: 0.1 | O37: 1138.17 | P37: 0.1 | Q37: 1138.17 | R37: 0.1 | S37: 1138.17 | T37: 0.1 | U37: 1138.17 | V37: 0.1 | W37: 1138.17 | X37: 0.1 | Y37: 1138.17 | Z37: 0.1 | AA37: 1138.17 | AB37: 0.1 | AC37: 1138.17 | AD37: 0.1 | AE37: 1138.17 | AF37: 0.1 | AG37: 1138.17 | AH37: 0.1 | AI37: =SUM(K37,M37,O37,Q37,S37,U37,W37, Y37,AA37,AC37,AE37,AG37) -> 13658.04
K38: =SUM(K30:K37) -> 11050 | L38: =SUM(L30:L37) -> 0.996 | M38: =SUM(M30:M37) -> 11050 | N38: =SUM(N30:N37) -> 1.003 | O38: =SUM(O30:O37) -> 11050 | P38: =SUM(P30:P37) -> 1.003 | Q38: =SUM(Q30:Q37) -> 11050 | R38: =SUM(R30:R37) -> 1.003 | ... AI38: =SUM(AI30:AI37) -> 132600 | AJ38: =SUM(AI31:AI37) -> 86654.81 | AK38: =(AJ38/AI38) -> 0.65350535
A40: SEWELL, DAN | F40: 2021-2022 | K40: 44378 | M40: 44409 | O40: 44440 | Q40: 44470 | S40: 44501 | U40: 44531 | W40: 44562 | Y40: 44593 | AA40: 44621 | AC40: 44652 | AE40: 44682 | AG40: 44713 | AI40: YTD SALARY SPLIT | AJ40: YTD OFFSET | AK40: YTD % Salary
A41: FUND | B41: ORG | C41: DEPT | D41: SDEPT | E41: GR-PR | F41: IACT | G41: OACT | H41: DACT | I41: FN | J41: ACCOUNT DESCRIPTION | K41: SALARY | L41: PERCENT | M41: SALARY | N41: PERCENT | O41: SALARY | P41: PERCENT | Q41: SALARY | R41: PERCENT | S41: SALARY | T41: PERCENT | U41: SALARY | V41: PERCENT | W41: SALARY | X41: PERCENT | Y41: SALARY | Z41: PERCENT | AA41: SALARY | AB41: PERCENT | AC41: SALARY | AD41: PERCENT | AE41: SALARY | AF41: PERCENT | AG41: SALARY | AH41: PERCENT
A42: 050 | B42: 20 | C42: 5220 | D42: 00000 | E42: 00000000 | F42: 5002 | G42: 000 | H42: 00000 | I42: 10 | J42: BIOSTAT GENERAL ACCT | K42: 5242.24 | L42: 0.52 | M42: 5242.24 | N42: 0.52 | O42: 5242.24 | P42: 0.52 | Q42: 5492.24 | R42: 0.52 | S42: 5492.24 | T42: 0.52 | U42: 5492.24 | V42: 0.52 | W42: 5695.75 | X42: 0.53 | Y42: 5695.75 | Z42: 0.53 | AA42: 5695.75 | AB42: 0.53 | AC42: 5695.75 | AD42: 0.53 | AE42: 5695.75 | AF42: 0.53 | AG42: 5695.75 | AH42: 0.53 | AI42: =SUM(K42,M42,O42,Q42,S42,U42,W42, Y42,AA42,AC42,AE42,AG42) -> 66377.94
A43: 510 | B43: 20 | C43: 5225 | D43: 00000 | E43: 11298401 | F43: 5002 | G43: 000 | H43: 00000 | I43: 20 | J43: PRC project | K43: 1012.5 | L43: 0.1 | M43: 1012.5 | N43: 0.1 | O43: 1012.5 | P43: 0.1 | Q43: 1012.5 | R43: 0.1 | S43: 1012.5 | T43: 0.1 | U43: 1012.5 | V43: 0.1 | W43: 1083.33 | X43: 0.09 | Y43: 1083.33 | Z43: 0.09 | AA43: 1083.33 | AB43: 0.09 | AC43: 1083.33 | AD43: 0.09 | AE43: 1083.33 | AF43: 0.09 | AG43: 1083.33 | AH43: 0.09 | AI43: =SUM(K43,M43,O43,Q43,S43,U43,W43, Y43,AA43,AC43,AE43,AG43) -> 12574.98
...

Sheet Summary
A1: Daniel Sewell, PhD
A2: Salary Offset Summary
A4: 2020-2021 | B4: 2021-2022 | C4: 2022-2023 | D4: 2023-2024 | E4: 2024-2025*
A5: ='Offset by year'!AK60 -> 0.81771525 | B5: ='Offset by year'!AK48 -> 0.47527287 | C5: ='Offset by year'!AK38 -> 0.65350535 | D5: ='Offset by year'!AK26 -> 0.70256033 | E5: ='Offset by year'!AK14 -> 0.80502786
D7: 4-Year Offset | E7: =AVERAGE(A5:D6) -> 0.66226345
D8: 5-Year Offset (includes current year) | E8: =AVERAGE(A5:E5) -> 0.69081633
